Workbook

Sheet CERTIFICADO
I3: Certificate No.: | K3: =QUADRO!I5 -> AZ25-094
I4: Certificado No.:
A6: CERTIFICATE OF RE-INSPECTION
A7: This is to certify that the raft detailed below has been surveyed, controlled and tested in compliance with requirements from:
B8: IPTM and the manufacturer and in acoordance with IMO Resolution: A.761(18)
A10: Identification: | C10: Type: | G10: Capacity: | I10: Serial No. | K10: Date of Manuf.:
A11: Identificação: | C11: Tipo: | G11: Capacidade: | I11: No. Série: | K11: Data de Fabr.:
C12: =QUADRO!H7 -> RFD SURVIVA MKIV | G12: =QUADRO!J7 -> 12 | I12: =QUADRO!C7 -> 5086010206436 | K12: =QUADRO!G79 -> 12/2021
C13: Fabric type: | G13: Length of painter: | J13: 44136 | K13: Max stowage height:
C14: Tipo de tela: | G14: Comp. da retenida: | K14: Altura máx. Lançamento:
C15: PU | G15: 28 | H15: m/inside | I15: 1 | J15: m/outside | K15: 18
A17: Cylinders: | C17: Serial No. | G17: Contents CO2 | I17: Contents N2 | K17: Latest hyd. Test
A18: Cilindros: | C18: No. Série | G18: Quantidade de Co2 | I18: Quantidade de N2 | K18: Último teste hidráulico
C19: =QUADRO!I56 -> 21W039093 | G19: =QUADRO!I62 -> 5.38 | I19: =QUADRO!I64 -> 0,270 | K19: =QUADRO!I66 -> 02/21
A24: Equipment: | C24: Unit | G24: Type | I24: Serial No. | K24: Expiry date
A25: Equipamento: | F25: 44136 | G25: Tipo | I25: No. Série | K25: Validade
C26: Emengency pack: | G26: =QUADRO!F47 -> SOLAS A | I26: =QUADRO!C7 -> 5086010206436 | K26: =QUADRO!F81+365 -> 46141
C27: Equi. de emerg.:
C28: EPIRB:
C29: 44136
C30: HRU test:
C31: Teste do Hidróstatico:
C32: Radar reflector:
C33: Reflector de Radar:
C34: First aid kit: | G34: SOLAS | K34: =QUADRO!J13 -> 01/2028
C35: Ambulância:
A38: Tests: | C38: NAP - test | G38: Gas inflation test | I38: Floor seam test | K38: Load test D. L.
A39: Testes:
C40: Yes/No | E40: NO | G40: Yes/No | H40: NO | I40: YES/NO | J40: NO | K40: Yes/No | L40: N/A
C41: Sim/Não | G41: Sim/Não | I41: Sim/Não | K41: Sim/Não
C42: Latest test: | G42: Latest test: | I42: Latest test: | K42: Latest test: | L42: =QUADRO!J53
C43: Último teste: | G43: Último teste: | I43: Último teste: | K43: Último teste:
A45: Verification: | C45: Date of inspection: | G45: Service station name and No. | K45: Date next inspection:
A46: Verificação: | C46: Data da inspecção: | G46: Nome e No. da Estação de Serviço | K46: Data da próxima inspecção:
C47: =QUADRO!F81 -> 45776 | G47: =QUADRO!C81 -> OREY TÉCNICA | K47: =C47+365 -> 46141
C49: National Marine | F49: Remarks/Modifications Observações/Modificações
C50: authority ID No. | F50: REPORT ANNEXED
B54: According to SOLAS regulation, this inflatable liferaft requires servicing within 12 months from the date of inspection.
B55: De acordo com a regulação SOLAS, esta jangada insuflavel requer inspecção dentro de 12 meses a partir da data de inspecção.
A57: Flag of Ship:
...

Sheet QUADRO
D3: QUADRO DE INSPECÇÃO DA JANGADA | H3: OBRA Nº:
D4: LIFERAFT INSPECTION SCHEDULE
H5: CERT. Nº | I5: AZ25-094
B7: JANGADA: | C7: 5086010206436 | D7: NAVIO: | E7: LAGRIMA DE CRISTO | G7: MARCA/MODELO: | H7: RFD SURVIVA MKIV | J7: 12
B8: LIFERAFT: | D8: SHIP: | G8: BRAND/TYPE:
B10: JANGADA - EXTERIOR | D10: Fecho da Cobertura | G10: Ajudas Térmicas
B11: LIFERAFT - EXTERNAL | D11: Closure for Canopy | G11: Thermal Protective Aids
B12: Cobertura Exterior | D12: Protectores de Juntas | G12: Ambulância
B13: Canopy External | D13: Seam Protective Tapes | G13: First Aid Kit | J13: 01/2028
B14: Saída de Antena | D14: Colectores de Água | G14: Comprimidos p/ Enjoo
B15: Aerial Outlet | D15: Water Collectors | G15: Seasickness Tables | J15: 09/24
B16: Reflectores | D16: Manual de Instruções | G16: Foguetões Paraquedas
B17: Reflective Tape | D17: Instructions Manual | G17: Parachute Rockets | J17: 02/25
B18: Tubo de Identificação | D18: Tecido de Câmara e Fundo | G18: Fachos de Mão
B19: Identificatior card / tube | D19: Tubes and Floor Fabric | G19: Handflares | J19: 02/25
B20: Protectores de Juntas | D20: Fecho do Saco de Emergência | G20: Potes de Fumo
B21: Seam Protecting Tapes | D21: Fastening for Emergency Pack | G21: Smoke Signals | J21: 02/25
B22: Câmara e Fundo | D22: Luz Interior e Bateria | G22: Lanterna
B23: Buoyancy Tubes and Floor | D23: Inside Light and Battery | F23: 10/26 | G23: Torch with Spares
B24: Sistema de Endireitar | D24: Bateria de Lítio | G24: Pilhas para Lanterna
B25: Righting System | D25: Lithium Battery | F25: 10/26 | G25: Torch Batteries
B26: Bolsas de Estabilização | D26: Válvulas de Insuflação | G26: Apito
B27: Stabilizing Pockets | D27: Inflation Valves | G27: Whistle
B28: Luz Exterior e Bateria | D28: Válvulas de Atestar | G28: Estojo de Pesca
B29: Top Light and Battery | C29: 10/26 | D29: Topping Up Valves | G29: Fishing Kit
B30: Bateria Activada | D30: Suporte de Antena | G30: Esponjas
B31: Seacell Battery | D31: Aerial Support | G31: Sponges
B32: Rampa ou Escada | D32: Arco e Cinta de Remate | G32: Abre-Latas
B33: Boarding Ramp or Ladder | D33: Arch and Rubber Band | G33: Tin Openers
B34: Válvulas Segurança e Tampões | D34: ÍNVOLUCRO | G34: Tesouras
B35: Relief Valves and Stoppers | C35: A3 | D35: CONTAINER | G35: Scissors
B36: União Banjo - Câmara Superior | D36: Cinta de Fecho | G36: Sacos para Enjoo
B37: Banjo Bolt - Lower Tube | D37: Bursting Band / Tape | G37: Seasickness Bags
B38: União Banjo - Câmara Inferior | D38: Saco de Retenida | G38: Heliógrafo
B39: Banjo Bolt - Lower Tube | D39: Painter Line Bag | G39: Signalling Mirror
B40: Grinalda e Espelhos | D40: Comprimento da Retenida | G40: Manual de Sobrevivência
B41: Grabline and Patches | D41: Leght Painter Line | F41: 28 MT | G41: Survival Manual
B42: Alça da Retenida e Espelhos | D42: Marcas do Invólucro | G42: Quadro de Sinais
B43: Crowfoot Bridle and Patches | D43: Markings on Container | G43: Signalling Table
B44: Tubos de Alta Pressão | D44: EQUIPAMENTO JANGADA | G44: Res. A761 (18) | I44: DATA
...
